<sdf version='1.6'>
  <world name='default'>
    <light name='sun' type='directional'>
      <cast_shadows>1</cast_shadows>
      <pose frame=''>0 0 10 0 -0 0</pose>
      <diffuse>0.8 0.8 0.8 1</diffuse>
      <specular>0.2 0.2 0.2 1</specular>
      <attenuation>
        <range>1000</range>
        <constant>0.9</constant>
        <linear>0.01</linear>
        <quadratic>0.001</quadratic>
      </attenuation>
      <direction>-0.5 0.1 -0.9</direction>
    </light>
    <model name='ground_plane'>
      <static>1</static>
      <link name='link'>
        <collision name='collision'>
          <geometry>
            <plane>
              <normal>0 0 1</normal>
              <size>100 100</size>
            </plane>
          </geometry>
          <surface>
            <friction>
              <ode>
                <mu>100</mu>
                <mu2>50</mu2>
              </ode>
              <torsional>
                <ode/>
              </torsional>
            </friction>
            <contact>
              <ode/>
            </contact>
            <bounce/>
          </surface>
          <max_contacts>10</max_contacts>
        </collision>
        <visual name='visual'>
          <cast_shadows>0</cast_shadows>
          <geometry>
            <plane>
              <normal>0 0 1</normal>
              <size>100 100</size>
            </plane>
          </geometry>
          <material>
            <script>
              <uri>file://media/materials/scripts/gazebo.material</uri>
              <name>Gazebo/Grey</name>
            </script>
          </material>
        </visual>
        <self_collide>0</self_collide>
        <enable_wind>0</enable_wind>
        <kinematic>0</kinematic>
      </link>
    </model>
    <model name='vehicle'>
      <link name='my_husky::base_link'>
        <collision name='collision'>
          <pose frame=''>0 0 0.1 0 -0 0</pose>
          <geometry>
            <box>
              <size>1.0074 0.5709 0.2675</size>
            </box>
          </geometry>
          <max_contacts>10</max_contacts>
          <surface>
            <contact>
              <ode/>
            </contact>
            <bounce/>
            <friction>
              <torsional>
                <ode/>
              </torsional>
              <ode/>
            </friction>
          </surface>
        </collision>
        <inertial>
          <mass>33.855</mass>
          <pose frame=''>-0.085613 -0.00084 0.238145 0 -0 0</pose>
          <inertia>
            <ixx>2.2343</ixx>
            <ixy>-0.023642</ixy>
            <ixz>0.275174</ixz>
            <iyy>3.42518</iyy>
            <iyz>0.00239624</iyz>
            <izz>2.1241</izz>
          </inertia>
        </inertial>
        <visual name='base'>
          <pose frame=''>0 0 0 0 -0 0</pose>
          <geometry>
            <mesh>
              <uri>model://husky/meshes/base_link.stl</uri>
            </mesh>
          </geometry>
          <material>
            <script>
              <name>Gazebo/FlatBlack</name>
              <uri>__default__</uri>
            </script>
          </material>
        </visual>
        <visual name='top_plate'>
          <pose frame=''>0 0 0 0 -0 0</pose>
          <geometry>
            <mesh>
              <uri>model://husky/meshes/top_plate.stl</uri>
            </mesh>
          </geometry>
          <material>
            <script>
              <name>Gazebo/Yellow</name>
              <uri>__default__</uri>
            </script>
          </material>
        </visual>
        <visual name='front_bumper'>
          <pose frame=''>0.47 0 0.091 0 -0 0</pose>
          <geometry>
            <mesh>
              <uri>model://husky/meshes/bumper.stl</uri>
            </mesh>
          </geometry>
          <material>
            <script>
              <name>Gazebo/FlatBlack</name>
              <uri>__default__</uri>
            </script>
          </material>
        </visual>
        <visual name='rear_bumper'>
          <pose frame=''>-0.47 0 0.091 0 -0 3.141</pose>
          <geometry>
            <mesh>
              <uri>model://husky/meshes/bumper.stl</uri>
            </mesh>
          </geometry>
          <material>
            <script>
              <name>Gazebo/FlatBlack</name>
              <uri>__default__</uri>
            </script>
          </material>
        </visual>
        <visual name='user_rail'>
          <pose frame=''>0.272 0 0.245 0 -0 0</pose>
          <geometry>
            <mesh>
              <uri>model://husky/meshes/user_rail.stl</uri>
            </mesh>
          </geometry>
          <material>
            <script>
              <name>Gazebo/Grey</name>
              <uri>__default__</uri>
            </script>
          </material>
        </visual>
        <pose frame=''>0.3 0.5 0.9 0 -0 0</pose>
        <self_collide>0</self_collide>
        <enable_wind>0</enable_wind>
        <kinematic>0</kinematic>
      </link>
      <link name='my_husky::back_left_wheel'>
        <pose frame=''>0.044 0.785475 0.935 0 -0 0</pose>
        <inertial>
          <mass>2.6357</mass>
          <pose frame=''>0 0 0 0 -0 0</pose>
          <inertia>
            <ixx>0.0246688</ixx>
            <ixy>0</ixy>
            <ixz>0</ixz>
            <iyy>0.0246688</iyy>
            <iyz>0</iyz>
            <izz>0.0441058</izz>
          </inertia>
        </inertial>
        <collision name='back_left_wheel_collision'>
          <pose frame=''>0 0 0 -1.5707 0 0</pose>
          <geometry>
            <cylinder>
              <radius>0.17775</radius>
              <length>0.1143</length>
            </cylinder>
          </geometry>
          <surface>
            <friction>
              <ode>
                <mu>100</mu>
                <mu2>100</mu2>
                <slip1>0</slip1>
                <slip2>0</slip2>
              </ode>
              <torsional>
                <ode/>
              </torsional>
            </friction>
            <contact>
              <ode/>
            </contact>
            <bounce/>
          </surface>
          <max_contacts>10</max_contacts>
        </collision>
        <visual name='my_husky::back_left_wheel'>
          <pose frame=''>0 0 0 -3.14159 0 0</pose>
          <geometry>
            <mesh>
              <uri>model://husky/meshes/wheel.stl</uri>
            </mesh>
          </geometry>
          <material>
            <script>
              <name>Gazebo/Grey</name>
              <uri>__default__</uri>
            </script>
          </material>
        </visual>
        <self_collide>0</self_collide>
        <enable_wind>0</enable_wind>
        <kinematic>0</kinematic>
      </link>
      <joint name='my_husky::back_left_joint' type='revolute'>
        <parent>my_husky::base_link</parent>
        <child>my_husky::back_left_wheel</child>
        <axis>
          <xyz>0 1 0</xyz>
          <use_parent_model_frame>1</use_parent_model_frame>
          <limit>
            <lower>-1e+16</lower>
            <upper>1e+16</upper>
          </limit>
          <dynamics>
            <spring_reference>0</spring_reference>
            <spring_stiffness>0</spring_stiffness>
          </dynamics>
        </axis>
        <physics>
          <ode>
            <limit>
              <cfm>0</cfm>
              <erp>0.9</erp>
            </limit>
          </ode>
        </physics>
      </joint>
      <link name='my_husky::back_right_wheel'>
        <pose frame=''>0.044 0.214525 0.935 0 -0 0</pose>
        <inertial>
          <mass>2.6357</mass>
          <pose frame=''>0 0 0 0 -0 0</pose>
          <inertia>
            <ixx>0.0246688</ixx>
            <ixy>0</ixy>
            <ixz>0</ixz>
            <iyy>0.0246688</iyy>
            <iyz>0</iyz>
            <izz>0.0441058</izz>
          </inertia>
        </inertial>
        <collision name='back_right_wheel_collision'>
          <pose frame=''>0 0 0 -1.5707 0 0</pose>
          <geometry>
            <cylinder>
              <radius>0.17775</radius>
              <length>0.1143</length>
            </cylinder>
          </geometry>
          <surface>
            <friction>
              <ode>
                <mu>100</mu>
                <mu2>100</mu2>
                <slip1>0</slip1>
                <slip2>0</slip2>
              </ode>
              <torsional>
                <ode/>
              </torsional>
            </friction>
            <contact>
              <ode/>
            </contact>
            <bounce/>
          </surface>
          <max_contacts>10</max_contacts>
        </collision>
        <visual name='my_husky::back_right_wheel'>
          <pose frame=''>0 0 0 -3.14159 0 0</pose>
          <geometry>
            <mesh>
              <uri>model://husky/meshes/wheel.stl</uri>
            </mesh>
          </geometry>
          <material>
            <script>
              <name>Gazebo/Grey</name>
              <uri>__default__</uri>
            </script>
          </material>
        </visual>
        <self_collide>0</self_collide>
        <enable_wind>0</enable_wind>
        <kinematic>0</kinematic>
      </link>
      <joint name='my_husky::back_right_joint' type='revolute'>
        <parent>my_husky::base_link</parent>
        <child>my_husky::back_right_wheel</child>
        <axis>
          <xyz>0 1 0</xyz>
          <use_parent_model_frame>1</use_parent_model_frame>
          <limit>
            <lower>-1e+16</lower>
            <upper>1e+16</upper>
          </limit>
          <dynamics>
            <spring_reference>0</spring_reference>
            <spring_stiffness>0</spring_stiffness>
          </dynamics>
        </axis>
        <physics>
          <ode>
            <limit>
              <cfm>0</cfm>
              <erp>0.9</erp>
            </limit>
          </ode>
        </physics>
      </joint>
      <link name='my_husky::front_left_wheel'>
        <pose frame=''>0.556 0.785475 0.935 0 -0 0</pose>
        <inertial>
          <mass>2.6357</mass>
          <pose frame=''>0 0 0 0 -0 0</pose>
          <inertia>
            <ixx>0.0246688</ixx>
            <ixy>0</ixy>
            <ixz>0</ixz>
            <iyy>0.0246688</iyy>
            <iyz>0</iyz>
            <izz>0.0441058</izz>
          </inertia>
        </inertial>
        <collision name='front_left_wheel_collision'>
          <pose frame=''>0 0 0 -1.5707 0 0</pose>
          <geometry>
            <cylinder>
              <radius>0.17775</radius>
              <length>0.1143</length>
            </cylinder>
          </geometry>
          <surface>
            <friction>
              <ode>
                <mu>100</mu>
                <mu2>100</mu2>
                <slip1>0</slip1>
                <slip2>0</slip2>
              </ode>
              <torsional>
                <ode/>
              </torsional>
            </friction>
            <contact>
              <ode/>
            </contact>
            <bounce/>
          </surface>
          <max_contacts>10</max_contacts>
        </collision>
        <visual name='my_husky::front_left_wheel'>
          <pose frame=''>0 0 0 -3.14159 0 0</pose>
          <geometry>
            <mesh>
              <uri>model://husky/meshes/wheel.stl</uri>
            </mesh>
          </geometry>
          <material>
            <script>
              <name>Gazebo/Grey</name>
              <uri>__default__</uri>
            </script>
          </material>
        </visual>
        <self_collide>0</self_collide>
        <enable_wind>0</enable_wind>
        <kinematic>0</kinematic>
      </link>
      <joint name='my_husky::front_left_joint' type='revolute'>
        <parent>my_husky::base_link</parent>
        <child>my_husky::front_left_wheel</child>
        <axis>
          <xyz>0 1 0</xyz>
          <use_parent_model_frame>1</use_parent_model_frame>
          <limit>
            <lower>-1e+16</lower>
            <upper>1e+16</upper>
          </limit>
          <dynamics>
            <spring_reference>0</spring_reference>
            <spring_stiffness>0</spring_stiffness>
          </dynamics>
        </axis>
        <physics>
          <ode>
            <limit>
              <cfm>0</cfm>
              <erp>0.9</erp>
            </limit>
          </ode>
        </physics>
      </joint>
      <link name='my_husky::front_right_wheel'>
        <pose frame=''>0.556 0.214525 0.935 0 -0 0</pose>
        <inertial>
          <mass>2.6357</mass>
          <pose frame=''>0 0 0 0 -0 0</pose>
          <inertia>
            <ixx>0.0246688</ixx>
            <ixy>0</ixy>
            <ixz>0</ixz>
            <iyy>0.0246688</iyy>
            <iyz>0</iyz>
            <izz>0.0441058</izz>
          </inertia>
        </inertial>
        <collision name='front_right_wheel_collision'>
          <pose frame=''>0 0 0 -1.5707 0 0</pose>
          <geometry>
            <cylinder>
              <radius>0.17775</radius>
              <length>0.1143</length>
            </cylinder>
          </geometry>
          <surface>
            <friction>
              <ode>
                <mu>100</mu>
                <mu2>100</mu2>
                <slip1>0</slip1>
                <slip2>0</slip2>
              </ode>
              <torsional>
                <ode/>
              </torsional>
            </friction>
            <contact>
              <ode/>
            </contact>
            <bounce/>
          </surface>
          <max_contacts>10</max_contacts>
        </collision>
        <visual name='my_husky::front_right_wheel'>
          <pose frame=''>0 0 0 -3.14159 0 0</pose>
          <geometry>
            <mesh>
              <uri>model://husky/meshes/wheel.stl</uri>
            </mesh>
          </geometry>
          <material>
            <script>
              <name>Gazebo/Grey</name>
              <uri>__default__</uri>
            </script>
          </material>
        </visual>
        <self_collide>0</self_collide>
        <enable_wind>0</enable_wind>
        <kinematic>0</kinematic>
      </link>
      <joint name='my_husky::front_right_joint' type='revolute'>
        <parent>my_husky::base_link</parent>
        <child>my_husky::front_right_wheel</child>
        <axis>
          <xyz>0 1 0</xyz>
          <use_parent_model_frame>1</use_parent_model_frame>
          <limit>
            <lower>-1e+16</lower>
            <upper>1e+16</upper>
          </limit>
          <dynamics>
            <spring_reference>0</spring_reference>
            <spring_stiffness>0</spring_stiffness>
          </dynamics>
        </axis>
        <physics>
          <ode>
            <limit>
              <cfm>0</cfm>
              <erp>0.9</erp>
            </limit>
          </ode>
        </physics>
      </joint>
      <link name='my_husky::cam_link'>
        <pose frame=''>0.5 0.5 1.2 0 -0 0</pose>
        <visual name='this_cam'>
          <geometry>
            <box>
              <size>0.1 0.1 0.1</size>
            </box>
          </geometry>
        </visual>
        <sensor name='camera1' type='camera'>
          <update_rate>30</update_rate>
          <camera name='head'>
            <horizontal_fov>1.39626</horizontal_fov>
            <image>
              <width>800</width>
              <height>800</height>
              <format>R8G8B8</format>
            </image>
            <clip>
              <near>0.02</near>
              <far>300</far>
            </clip>
            <noise>
              <type>gaussian</type>
              <mean>0</mean>
              <stddev>0.007</stddev>
            </noise>
          </camera>
          <visualize>1</visualize>
          <plugin name='camera_controller' filename='libgazebo_ros_camera.so'>
            <alwaysOn>1</alwaysOn>
            <updateRate>0.0</updateRate>
            <cameraName>my_husky/camera1</cameraName>
            <imageTopicName>image_raw</imageTopicName>
            <cameraInfoTopicName>camera_info</cameraInfoTopicName>
            <frameName>my_husky::cam_link</frameName>
            <hackBaseline>0.07</hackBaseline>
            <distortionK1>0.0</distortionK1>
            <distortionK2>0.0</distortionK2>
            <distortionK3>0.0</distortionK3>
            <distortionT1>0.0</distortionT1>
            <distortionT2>0.0</distortionT2>
          </plugin>
        </sensor>
        <self_collide>0</self_collide>
        <inertial>
          <pose frame=''>0 0 0 0 -0 0</pose>
          <inertia>
            <ixx>1</ixx>
            <ixy>0</ixy>
            <ixz>0</ixz>
            <iyy>1</iyy>
            <iyz>0</iyz>
            <izz>1</izz>
          </inertia>
          <mass>1</mass>
        </inertial>
        <enable_wind>0</enable_wind>
        <kinematic>0</kinematic>
      </link>
      <joint name='my_husky::mycam_joint' type='fixed'>
        <parent>my_husky::base_link</parent>
        <child>my_husky::cam_link</child>
      </joint>
      <plugin name='skid_steer_drive_controller' filename='libgazebo_ros_skid_steer_drive.so'>
        <updateRate>100.0</updateRate>
        <robotNamespace>/my_husky</robotNamespace>
        <leftFrontJoint>my_husky::front_left_joint</leftFrontJoint>
        <rightFrontJoint>my_husky::front_right_joint</rightFrontJoint>
        <leftRearJoint>my_husky::back_left_joint</leftRearJoint>
        <rightRearJoint>my_husky::back_right_joint</rightRearJoint>
        <wheelSeparation>0.5709</wheelSeparation>
        <wheelDiameter>0.3555</wheelDiameter>
        <robotBaseFrame>my_husky::cam_link</robotBaseFrame>
        <torque>100</torque>
        <topicName>cmd_vel</topicName>
        <commandTopic>cmd_vel</commandTopic>
        <broadcastTF>1</broadcastTF>
      </plugin>
    </model>
    <gravity>0 0 -9.8</gravity>
    <magnetic_field>6e-06 2.3e-05 -4.2e-05</magnetic_field>
    <atmosphere type='adiabatic'/>
    <physics name='default_physics' default='0' type='ode'>
      <max_step_size>0.001</max_step_size>
      <real_time_factor>1</real_time_factor>
      <real_time_update_rate>1000</real_time_update_rate>
    </physics>
    <scene>
      <ambient>0.4 0.4 0.4 1</ambient>
      <background>0.7 0.7 0.7 1</background>
      <shadows>1</shadows>
    </scene>
    <wind/>
    <spherical_coordinates>
      <surface_model>EARTH_WGS84</surface_model>
      <latitude_deg>0</latitude_deg>
      <longitude_deg>0</longitude_deg>
      <elevation>0</elevation>
      <heading_deg>0</heading_deg>
    </spherical_coordinates>
    <model name='sonoma_raceway'>
      <pose frame=''>-275.858 132.309 -4.8 0 -0 0</pose>
      <static>1</static>
      <link name='link'>
        <collision name='collision'>
          <geometry>
            <mesh>
              <uri>model://sonoma_raceway/meshes/Raceway.obj</uri>
              <scale>0.0254 0.0254 0.0254</scale>
            </mesh>
          </geometry>
          <max_contacts>10</max_contacts>
          <surface>
            <contact>
              <ode/>
            </contact>
            <bounce/>
            <friction>
              <torsional>
                <ode/>
              </torsional>
              <ode/>
            </friction>
          </surface>
        </collision>
        <visual name='visual'>
          <geometry>
            <mesh>
              <uri>model://sonoma_raceway/meshes/Raceway.obj</uri>
              <scale>0.0254 0.0254 0.0254</scale>
            </mesh>
          </geometry>
        </visual>
        <self_collide>0</self_collide>
        <enable_wind>0</enable_wind>
        <kinematic>0</kinematic>
      </link>
    </model>
    <state world_name='default'>
      <sim_time>159 763000000</sim_time>
      <real_time>160 494485375</real_time>
      <wall_time>1606209153 830244631</wall_time>
      <iterations>159763</iterations>
      <model name='ground_plane'>
        <pose frame=''>0 0 0 0 -0 0</pose>
        <scale>1 1 1</scale>
        <link name='link'>
          <pose frame=''>0 0 0 0 -0 0</pose>
          <velocity>0 0 0 0 -0 0</velocity>
          <acceleration>0 0 0 0 -0 0</acceleration>
          <wrench>0 0 0 0 -0 0</wrench>
        </link>
      </model>
      <model name='sonoma_raceway'>
        <pose frame=''>-276.961 136.73 -4.8 0 -0 0</pose>
        <scale>1 1 1</scale>
        <link name='link'>
          <pose frame=''>-276.961 136.73 -4.8 0 -0 0</pose>
          <velocity>0 0 0 0 -0 0</velocity>
          <acceleration>0 0 0 0 -0 0</acceleration>
          <wrench>0 0 0 0 -0 0</wrench>
        </link>
      </model>
      <model name='vehicle'>
        <pose frame=''>6.10907 -4.18309 1.92987 -0.001875 0.020114 -0.799699</pose>
        <scale>1 1 1</scale>
        <link name='my_husky::back_left_wheel'>
          <pose frame=''>6.71737 -3.67947 2.86232 -0.001889 0.009725 -0.79968</pose>
          <velocity>0.00081 0.000361 -0.005605 0.002654 -0.002497 -0.000548</velocity>
          <acceleration>0.188949 0.148477 -9.95882 -2.0212 0.902582 0.033444</acceleration>
          <wrench>0.498013 0.391342 -26.2485 0 -0 0</wrench>
        </link>
        <link name='my_husky::back_right_wheel'>
          <pose frame=''>6.30794 -4.07739 2.86339 -0.001896 -0.093242 -0.799485</pose>
          <velocity>0.000576 0.000634 -0.00558 0.002557 -0.002397 -0.000529</velocity>
          <acceleration>0.180103 0.219521 -9.63751 2.08766 0.885505 -2.78688</acceleration>
          <wrench>0.474699 0.57859 -25.4016 0 -0 0</wrench>
        </link>
        <link name='my_husky::base_link'>
          <pose frame=''>6.69049 -4.06152 2.82271 -0.001875 0.020114 -0.799699</pose>
          <velocity>0.000462 0.00028 -0.005637 0.000226 1e-06 -0.000563</velocity>
          <acceleration>-0.043401 -0.044152 -9.80169 -0.124457 0.165997 0.049599</acceleration>
          <wrench>-1.46932 -1.49477 -331.836 0 -0 0</wrench>
        </link>
        <link name='my_husky::cam_link'>
          <pose frame=''>6.83446 -4.20885 3.11863 -0.001875 0.020114 -0.799699</pose>
          <velocity>0.000373 0.000126 -0.00567 0.000229 -1e-06 -0.000558</velocity>
          <acceleration>-0.040793 -0.042683 -9.80146 -0.107527 0.107547 0.046794</acceleration>
          <wrench>-0.040793 -0.042683 -9.80146 0 -0 0</wrench>
        </link>
        <link name='my_husky::front_left_wheel'>
          <pose frame=''>7.07413 -4.04657 2.85202 -0.001885 0.039192 -0.799735</pose>
          <velocity>0.000557 0.00012 -0.005685 0.001795 -0.001613 -0.000532</velocity>
          <acceleration>0.106374 0.072001 -9.94825 -0.648597 0.433505 -3.11966</acceleration>
          <wrench>0.28037 0.189772 -26.2206 0 -0 0</wrench>
        </link>
        <link name='my_husky::front_right_wheel'>
          <pose frame=''>6.66469 -4.44449 2.85309 -0.001887 -0.063649 -0.799541</pose>
          <velocity>0.000322 0.000392 -0.005663 0.001698 -0.001514 -0.000593</velocity>
          <acceleration>0.097521 0.143321 -9.63312 0.309486 -0.890435 -3.07281</acceleration>
          <wrench>0.257037 0.377752 -25.39 0 -0 0</wrench>
        </link>
      </model>
      <light name='sun'>
        <pose frame=''>0 0 10 0 -0 0</pose>
      </light>
    </state>
    <gui fullscreen='0'>
      <camera name='user_camera'>
        <pose frame=''>0.237179 1.74252 9.70336 -0 0.623643 -0.835003</pose>
        <view_controller>orbit</view_controller>
        <projection_type>perspective</projection_type>
      </camera>
    </gui>
  </world>
</sdf>
